<?xml version="1.0" ?>
<!-- Generated using onshape-to-robot -->
<!-- Onshape https://cad.onshape.com/documents/8728c7fdb0e0b3c78180e1fb/w/25c822efb72989a8d89a69ff/e/c77dbd6d3fbd22e2e0636f89 -->
<mujoco model="openarm_gripette_right">
  <compiler angle="radian" meshdir="assets" autolimits="true"/>
  <default>
    <default class="openarm_gripette_right">
      <joint frictionloss="0.1" armature="0.1"/>
      <position kp="500" dampratio="1"/>
      <default class="visual">
        <geom type="mesh" contype="0" conaffinity="0" group="2"/>
      </default>
      <default class="collision">
        <geom group="3" contype="2" conaffinity="1"/>
      </default>
    </default>
  </default>
  <worldbody>
    <!-- Link hfsb6_6060_750_1_step -->
    <body name="hfsb6_6060_750_1_step" pos="0 0 0" quat="1 0 0 0" childclass="openarm_gripette_right">
      <inertial pos="0 0 0" mass="1e-09" fullinertia="1e-09 1e-09 1e-09 0 0 0"/>
      <!-- Part j1_b_2_step -->
      <geom type="mesh" class="visual" pos="1e-12 3e-12 -0.008" quat="1 0 0 -0" mesh="j1_b_2_step" material="j1_b_2_step_material"/>
      <geom type="mesh" class="collision" pos="1e-12 3e-12 -0.008" quat="1 0 0 -0" mesh="j1_b_2_step" material="j1_b_2_step_material"/>
      <!-- Part hfsb6_6060_750_1_step -->
      <geom type="mesh" class="visual" pos="-4e-12 -3e-12 0.758" quat="0 -0.707107 0.707107 -0" mesh="hfsb6_6060_750_1_step" material="hfsb6_6060_750_1_step_material"/>
      <geom type="mesh" class="collision" pos="-4e-12 -3e-12 0.758" quat="0 -0.707107 0.707107 -0" mesh="hfsb6_6060_750_1_step" material="hfsb6_6060_750_1_step_material"/>
      <!-- Part dm_j8009p_2_step -->
      <geom type="mesh" class="visual" pos="1e-12 3e-12 -0.008" quat="1 0 -0 -0" mesh="dm_j8009p_2_step" material="dm_j8009p_2_step_material"/>
      <geom type="mesh" class="collision" pos="1e-12 3e-12 -0.008" quat="1 0 -0 -0" mesh="dm_j8009p_2_step" material="dm_j8009p_2_step_material"/>
      <!-- Part j1_a_1_step -->
      <geom type="mesh" class="visual" pos="1e-12 3e-12 -0.008" quat="1 0 -0 -0" mesh="j1_a_1_step" material="j1_a_1_step_material"/>
      <geom type="mesh" class="collision" pos="1e-12 3e-12 -0.008" quat="1 0 -0 -0" mesh="j1_a_1_step" material="j1_a_1_step_material"/>
      <!-- Link dm_j8009p_2_step_1 -->
      <body name="dm_j8009p_2_step_1" pos="-0 -0.0925 0.689" quat="0.707107 0.707107 -0 -0">
        <!-- Joint from hfsb6_6060_750_1_step to dm_j8009p_2_step_1 -->
        <joint axis="0 0 1" name="r_arm_pitch" type="hinge" range="-1.3962634015954636 3.490658503988659"/>
        <inertial pos="0 0 0" mass="1e-09" fullinertia="1e-09 1e-09 1e-09 0 0 0"/>
        <!-- Part dm_j8009p_2_step_1 -->
        <geom type="mesh" class="visual" pos="1e-12 -0.697 -0.0925" quat="0.707107 -0.707107 0 0" mesh="dm_j8009p_2_step_1" material="dm_j8009p_2_step_1_material"/>
        <geom type="mesh" class="collision" pos="1e-12 -0.697 -0.0925" quat="0.707107 -0.707107 0 0" mesh="dm_j8009p_2_step_1" material="dm_j8009p_2_step_1_material"/>
        <!-- Part j1_e_1_step -->
        <geom type="mesh" class="visual" pos="1e-12 -0.697 -0.0925" quat="0.707107 -0.707107 0 0" mesh="j1_e_1_step" material="j1_e_1_step_material"/>
        <geom type="mesh" class="collision" pos="1e-12 -0.697 -0.0925" quat="0.707107 -0.707107 0 0" mesh="j1_e_1_step" material="j1_e_1_step_material"/>
        <!-- Part j1_d_1_step -->
        <geom type="mesh" class="visual" pos="1e-12 -0.697 -0.0925" quat="0.707107 -0.707107 0 0" mesh="j1_d_1_step" material="j1_d_1_step_material"/>
        <geom type="mesh" class="collision" pos="1e-12 -0.697 -0.0925" quat="0.707107 -0.707107 0 0" mesh="j1_d_1_step" material="j1_d_1_step_material"/>
        <!-- Part j1_c_1_step -->
        <geom type="mesh" class="visual" pos="1e-12 -0.697 -0.0925" quat="0.707107 -0.707107 0 0" mesh="j1_c_1_step" material="j1_c_1_step_material"/>
        <geom type="mesh" class="collision" pos="1e-12 -0.697 -0.0925" quat="0.707107 -0.707107 0 0" mesh="j1_c_1_step" material="j1_c_1_step_material"/>
        <!-- Link j2_b_2_step -->
        <body name="j2_b_2_step" pos="-0.0301 -0 0.06" quat="0 0.707107 -0 -0.707107">
          <!-- Joint from dm_j8009p_2_step_1 to j2_b_2_step -->
          <joint axis="0 0 1" name="r_arm_roll" type="hinge" range="-1.7453292519943278 1.7453292519943313"/>
          <inertial pos="0 0 0" mass="1e-09" fullinertia="1e-09 1e-09 1e-09 0 0 0"/>
          <!-- Part j2_a_1_step -->
          <geom type="mesh" class="visual" pos="0.1525 0.697 -0.0301" quat="0.5 0.5 0.5 -0.5" mesh="j2_a_1_step" material="j2_a_1_step_material"/>
          <geom type="mesh" class="collision" pos="0.1525 0.697 -0.0301" quat="0.5 0.5 0.5 -0.5" mesh="j2_a_1_step" material="j2_a_1_step_material"/>
          <!-- Part j2_c_2_step -->
          <geom type="mesh" class="visual" pos="0.1525 0.697 -0.0301" quat="0.5 0.5 0.5 -0.5" mesh="j2_c_2_step" material="j2_c_2_step_material"/>
          <geom type="mesh" class="collision" pos="0.1525 0.697 -0.0301" quat="0.5 0.5 0.5 -0.5" mesh="j2_c_2_step" material="j2_c_2_step_material"/>
          <!-- Part j2_b_2_step -->
          <geom type="mesh" class="visual" pos="0.1525 0.697 -0.0301" quat="0.5 0.5 0.5 -0.5" mesh="j2_b_2_step" material="j2_b_2_step_material"/>
          <geom type="mesh" class="collision" pos="0.1525 0.697 -0.0301" quat="0.5 0.5 0.5 -0.5" mesh="j2_b_2_step" material="j2_b_2_step_material"/>
          <!-- Link dm_j4340_2_step -->
          <body name="dm_j4340_2_step" pos="-0 0.06625 -0.0301" quat="0.5 -0.5 0.5 0.5">
            <!-- Joint from j2_b_2_step to dm_j4340_2_step -->
            <joint axis="0 0 1" name="r_arm_yaw" type="hinge" range="-1.5707963267948957 1.5707963267948974"/>
            <inertial pos="0 0 0" mass="1e-09" fullinertia="1e-09 1e-09 1e-09 0 0 0"/>
            <!-- Part dm_j4340p_2_step -->
            <geom type="mesh" class="visual" pos="1e-12 -0.1525 0.63075" quat="0 -1 0 0" mesh="dm_j4340p_2_step" material="dm_j4340p_2_step_material"/>
            <geom type="mesh" class="collision" pos="1e-12 -0.1525 0.63075" quat="0 -1 0 0" mesh="dm_j4340p_2_step" material="dm_j4340p_2_step_material"/>
            <!-- Part fl6803zz_2_step -->
            <geom type="mesh" class="visual" pos="1e-12 -0.1525 0.63075" quat="0 -1 0 0" mesh="fl6803zz_2_step" material="fl6803zz_2_step_material"/>
            <geom type="mesh" class="collision" pos="1e-12 -0.1525 0.63075" quat="0 -1 0 0" mesh="fl6803zz_2_step" material="fl6803zz_2_step_material"/>
            <!-- Part j4_a_2_step -->
            <geom type="mesh" class="visual" pos="1e-12 -0.1525 0.63075" quat="0 -1 0 0" mesh="j4_a_2_step" material="j4_a_2_step_material"/>
            <geom type="mesh" class="collision" pos="1e-12 -0.1525 0.63075" quat="0 -1 0 0" mesh="j4_a_2_step" material="j4_a_2_step_material"/>
            <!-- Part dm_j4340_2_step -->
            <geom type="mesh" class="visual" pos="1e-12 -0.1525 0.63075" quat="0 -1 0 0" mesh="dm_j4340_2_step" material="dm_j4340_2_step_material"/>
            <geom type="mesh" class="collision" pos="1e-12 -0.1525 0.63075" quat="0 -1 0 0" mesh="dm_j4340_2_step" material="dm_j4340_2_step_material"/>
            <!-- Part j4_b_2_step -->
            <geom type="mesh" class="visual" pos="1e-12 -0.1525 0.63075" quat="0 -1 0 0" mesh="j4_b_2_step" material="j4_b_2_step_material"/>
            <geom type="mesh" class="collision" pos="1e-12 -0.1525 0.63075" quat="0 -1 0 0" mesh="j4_b_2_step" material="j4_b_2_step_material"/>
            <!-- Link dm_j4310_1_2_step -->
            <body name="dm_j4310_1_2_step" pos="0 0.03155 0.15375" quat="0.707107 -0.707107 0 0">
              <!-- Joint from dm_j4340_2_step to dm_j4310_1_2_step -->
              <joint axis="0 0 1" name="r_elbow" type="hinge" range="0.0 2.443460952792061"/>
              <inertial pos="0 0 0" mass="1e-09" fullinertia="1e-09 1e-09 1e-09 0 0 0"/>
              <!-- Part j4_d_2_step -->
              <geom type="mesh" class="visual" pos="1e-12 -0.477 -0.18405" quat="0.707107 -0.707107 0 0" mesh="j4_d_2_step" material="j4_d_2_step_material"/>
              <geom type="mesh" class="collision" pos="1e-12 -0.477 -0.18405" quat="0.707107 -0.707107 0 0" mesh="j4_d_2_step" material="j4_d_2_step_material"/>
              <!-- Part j4_c_2_step -->
              <geom type="mesh" class="visual" pos="1e-12 -0.477 -0.18405" quat="0.707107 -0.707107 0 0" mesh="j4_c_2_step" material="j4_c_2_step_material"/>
              <geom type="mesh" class="collision" pos="1e-12 -0.477 -0.18405" quat="0.707107 -0.707107 0 0" mesh="j4_c_2_step" material="j4_c_2_step_material"/>
              <!-- Part dm_j4310_1_2_step -->
              <geom type="mesh" class="visual" pos="1e-12 -0.477 -0.18405" quat="0.707107 -0.707107 -0 -0" mesh="dm_j4310_1_2_step" material="dm_j4310_1_2_step_material"/>
              <geom type="mesh" class="collision" pos="1e-12 -0.477 -0.18405" quat="0.707107 -0.707107 -0 -0" mesh="dm_j4310_1_2_step" material="dm_j4310_1_2_step_material"/>
              <!-- Part j4_e_2_step -->
              <geom type="mesh" class="visual" pos="1e-12 -0.477 -0.18405" quat="0.707107 -0.707107 0 0" mesh="j4_e_2_step" material="j4_e_2_step_material"/>
              <geom type="mesh" class="collision" pos="1e-12 -0.477 -0.18405" quat="0.707107 -0.707107 0 0" mesh="j4_e_2_step" material="j4_e_2_step_material"/>
              <!-- Link j6_a_3_step -->
              <body name="j6_a_3_step" pos="-0 -0.0955 -0.0315" quat="0.707107 0.707107 -0 -0">
                <!-- Joint from dm_j4310_1_2_step to j6_a_3_step -->
                <joint axis="0 0 1" name="r_wrist_yaw" type="hinge" range="-1.570796326794886 1.5707963267949072"/>
                <inertial pos="0 0 0" mass="1e-09" fullinertia="1e-09 1e-09 1e-09 0 0 0"/>
                <!-- Part j6_d_3_step -->
                <geom type="mesh" class="visual" pos="1e-12 -0.15255 0.3815" quat="0 -1 0 0" mesh="j6_d_3_step" material="j6_d_3_step_material"/>
                <geom type="mesh" class="collision" pos="1e-12 -0.15255 0.3815" quat="0 -1 0 0" mesh="j6_d_3_step" material="j6_d_3_step_material"/>
                <!-- Part dm_j4310_1_2_step_1 -->
                <geom type="mesh" class="visual" pos="1e-12 -0.15255 0.3815" quat="0 -1 0 0" mesh="dm_j4310_1_2_step_1" material="dm_j4310_1_2_step_1_material"/>
                <geom type="mesh" class="collision" pos="1e-12 -0.15255 0.3815" quat="0 -1 0 0" mesh="dm_j4310_1_2_step_1" material="dm_j4310_1_2_step_1_material"/>
                <!-- Part j6_b_3_step -->
                <geom type="mesh" class="visual" pos="1e-12 -0.15255 0.3815" quat="0 -1 0 0" mesh="j6_b_3_step" material="j6_b_3_step_material"/>
                <geom type="mesh" class="collision" pos="1e-12 -0.15255 0.3815" quat="0 -1 0 0" mesh="j6_b_3_step" material="j6_b_3_step_material"/>
                <!-- Part j5_a_3_step -->
                <geom type="mesh" class="visual" pos="1e-12 -0.15255 0.3815" quat="0 -1 0 0" mesh="j5_a_3_step" material="j5_a_3_step_material"/>
                <geom type="mesh" class="collision" pos="1e-12 -0.15255 0.3815" quat="0 -1 0 0" mesh="j5_a_3_step" material="j5_a_3_step_material"/>
                <!-- Part j6_a_3_step -->
                <geom type="mesh" class="visual" pos="1e-12 -0.15255 0.3815" quat="0 -1 0 0" mesh="j6_a_3_step" material="j6_a_3_step_material"/>
                <geom type="mesh" class="collision" pos="1e-12 -0.15255 0.3815" quat="0 -1 0 0" mesh="j6_a_3_step" material="j6_a_3_step_material"/>
                <!-- Part j6_c_right_2_step -->
                <geom type="mesh" class="visual" pos="1e-12 -0.15255 0.3815" quat="0 -1 0 0" mesh="j6_c_right_2_step" material="j6_c_right_2_step_material"/>
                <geom type="mesh" class="collision" pos="1e-12 -0.15255 0.3815" quat="0 -1 0 0" mesh="j6_c_right_2_step" material="j6_c_right_2_step_material"/>
                <!-- Link j7_e_2_step -->
                <body name="j7_e_2_step" pos="0.0172 -0 0.0455" quat="0.49946 0.500539 -0.49946 -0.500539">
                  <!-- Joint from j6_a_3_step to j7_e_2_step -->
                  <joint axis="0 0 1" name="r_wrist_roll" type="hinge" range="-0.7832396212099086 0.7875563787900914"/>
                  <inertial pos="0 0 0" mass="1e-09" fullinertia="1e-09 1e-09 1e-09 0 0 0"/>
                  <!-- Part j7_e_2_step -->
                  <geom type="mesh" class="visual" pos="0.15255 0.336 0.0172" quat="0.5 0.5 0.5 -0.5" mesh="j7_e_2_step" material="j7_e_2_step_material"/>
                  <geom type="mesh" class="collision" pos="0.15255 0.336 0.0172" quat="0.5 0.5 0.5 -0.5" mesh="j7_e_2_step" material="j7_e_2_step_material"/>
                </body>
                <!-- Link dm_j4310_1_2_step_2 -->
                <body name="dm_j4310_1_2_step_2" pos="0.0343 -0 0.1205" quat="0.49946 0.500539 0.49946 0.500539">
                  <!-- Joint from j6_a_3_step to dm_j4310_1_2_step_2 -->
                  <joint axis="0 0 1" name="r_wrist_roll_mimic" type="hinge"/>
                  <inertial pos="0 0 0" mass="1e-09" fullinertia="1e-09 1e-09 1e-09 0 0 0"/>
                  <!-- Part fl6700zz_2_step -->
                  <geom type="mesh" class="visual" pos="0.15255 -0.261 -0.0343" quat="0.5 -0.5 -0.5 -0.5" mesh="fl6700zz_2_step" material="fl6700zz_2_step_material"/>
                  <geom type="mesh" class="collision" pos="0.15255 -0.261 -0.0343" quat="0.5 -0.5 -0.5 -0.5" mesh="fl6700zz_2_step" material="fl6700zz_2_step_material"/>
                  <!-- Part dm_j4310_1_2_step_2 -->
                  <geom type="mesh" class="visual" pos="-0.15255 0.261 -0.0343" quat="0.5 0.5 -0.5 0.5" mesh="dm_j4310_1_2_step_2" material="dm_j4310_1_2_step_2_material"/>
                  <geom type="mesh" class="collision" pos="-0.15255 0.261 -0.0343" quat="0.5 0.5 -0.5 0.5" mesh="dm_j4310_1_2_step_2" material="dm_j4310_1_2_step_2_material"/>
                  <!-- Part j7_b_2_step -->
                  <geom type="mesh" class="visual" pos="-0.15255 -0.261 -0.0343" quat="0.5 -0.5 0.5 0.5" mesh="j7_b_2_step" material="j7_b_2_step_material"/>
                  <geom type="mesh" class="collision" pos="-0.15255 -0.261 -0.0343" quat="0.5 -0.5 0.5 0.5" mesh="j7_b_2_step" material="j7_b_2_step_material"/>
                  <!-- Part j7_a_2_step -->
                  <geom type="mesh" class="visual" pos="-0.15255 0.261 -0.0343" quat="0.5 0.5 -0.5 0.5" mesh="j7_a_2_step" material="j7_a_2_step_material"/>
                  <geom type="mesh" class="collision" pos="-0.15255 0.261 -0.0343" quat="0.5 0.5 -0.5 0.5" mesh="j7_a_2_step" material="j7_a_2_step_material"/>
                  <!-- Part j7_c_2_step -->
                  <geom type="mesh" class="visual" pos="-0.15255 0.261 -0.0343" quat="0.5 0.5 -0.5 0.5" mesh="j7_c_2_step" material="j7_c_2_step_material"/>
                  <geom type="mesh" class="collision" pos="-0.15255 0.261 -0.0343" quat="0.5 0.5 -0.5 0.5" mesh="j7_c_2_step" material="j7_c_2_step_material"/>
                  <!-- Part fl6700zz_2_step_1 -->
                  <geom type="mesh" class="visual" pos="0.15255 -0.261 -0.0343" quat="0.5 -0.5 -0.5 -0.5" mesh="fl6700zz_2_step_1" material="fl6700zz_2_step_1_material"/>
                  <geom type="mesh" class="collision" pos="0.15255 -0.261 -0.0343" quat="0.5 -0.5 -0.5 -0.5" mesh="fl6700zz_2_step_1" material="fl6700zz_2_step_1_material"/>
                  <!-- Part j7_b_2_step_2 -->
                  <geom type="mesh" class="visual" pos="-0.15245 0.261 -0.0343" quat="0.5 0.5 0.5 -0.5" mesh="j7_b_2_step_2" material="j7_b_2_step_2_material"/>
                  <geom type="mesh" class="collision" pos="-0.15245 0.261 -0.0343" quat="0.5 0.5 0.5 -0.5" mesh="j7_b_2_step_2" material="j7_b_2_step_2_material"/>
                  <!-- Link j8_a_2_step -->
                  <body name="j8_a_2_step" pos="0.0205 0 -0.0343" quat="0.00221726 0.707103 0.00221726 0.707103">
                    <!-- Joint from dm_j4310_1_2_step_2 to j8_a_2_step -->
                    <joint axis="0 0 1" name="r_wrist_pitch" type="hinge" range="-1.5645249569847266 1.5770676966050665"/>
                    <inertial pos="0.0168653 -0.0836013 -0.0169536" mass="0.227294" fullinertia="0.000379489 0.000539617 0.000403409 -7.53636e-05 2.59208e-05 -3.44239e-05"/>
                    <!-- Part 611_00020_1 -->
                    <geom type="mesh" class="visual" pos="0.0400246 -0.072 0.00845136" quat="0.5 0.5 0.5 -0.5" mesh="611_00020_1" material="611_00020_1_material"/>
                    <geom type="mesh" class="collision" pos="0.0400246 -0.072 0.00845136" quat="0.5 0.5 0.5 -0.5" mesh="611_00020_1" material="611_00020_1_material"/>
                    <!-- Part sr_lens_py058 -->
                    <geom type="mesh" class="visual" pos="0.0400246 -0.072 0.00845136" quat="0.5 0.5 0.5 -0.5" mesh="sr_lens_py058" material="sr_lens_py058_material"/>
                    <geom type="mesh" class="collision" pos="0.0400246 -0.072 0.00845136" quat="0.5 0.5 0.5 -0.5" mesh="sr_lens_py058" material="sr_lens_py058_material"/>
                    <!-- Part std00333_plast_tcb_torx_2_5x8__configuration_copy_of_default -->
                    <geom type="mesh" class="visual" pos="-0 -0.129426 -0.0833323" quat="0.589226 -0.390912 -0.390912 -0.589226" mesh="std00333_plast_tcb_torx_2_5x8__configuration_copy_of_default" material="std00333_plast_tcb_torx_2_5x8__configuration_copy_of_default_material"/>
                    <geom type="mesh" class="collision" pos="-0 -0.129426 -0.0833323" quat="0.589226 -0.390912 -0.390912 -0.589226" mesh="std00333_plast_tcb_torx_2_5x8__configuration_copy_of_default" material="std00333_plast_tcb_torx_2_5x8__configuration_copy_of_default_material"/>
                    <!-- Part hex_socket_head_cap_screw_m4x0_70_x_8__a416dc2a8d778a4ef6150c0739aa89d1 -->
                    <geom type="mesh" class="visual" pos="0.0554246 -0.0485 0.00845136" quat="0.5 -0.5 -0.5 -0.5" mesh="hex_socket_head_cap_screw_m4x0_70_x_8__a416dc2a8d778a4ef6150c0739aa89d1" material="hex_socket_head_cap_screw_m4x0_70_x_8__a416dc2a8d778a4ef6150c0739aa89d1_material"/>
                    <geom type="mesh" class="collision" pos="0.0554246 -0.0485 0.00845136" quat="0.5 -0.5 -0.5 -0.5" mesh="hex_socket_head_cap_screw_m4x0_70_x_8__a416dc2a8d778a4ef6150c0739aa89d1" material="hex_socket_head_cap_screw_m4x0_70_x_8__a416dc2a8d778a4ef6150c0739aa89d1_material"/>
                    <!-- Part std00333_plast_tcb_torx_2_5x8__configuration_copy_of_default_2 -->
                    <geom type="mesh" class="visual" pos="-0.019 -0.13453 -0.0686628" quat="0.589226 -0.390912 -0.390912 -0.589226" mesh="std00333_plast_tcb_torx_2_5x8__configuration_copy_of_default" material="std00333_plast_tcb_torx_2_5x8__configuration_copy_of_default_material"/>
                    <geom type="mesh" class="collision" pos="-0.019 -0.13453 -0.0686628" quat="0.589226 -0.390912 -0.390912 -0.589226" mesh="std00333_plast_tcb_torx_2_5x8__configuration_copy_of_default" material="std00333_plast_tcb_torx_2_5x8__configuration_copy_of_default_material"/>
                    <!-- Part feetech_pt_screw_2x6__configuration_default -->
                    <geom type="mesh" class="visual" pos="0.0177 -0.07175 0.0477356" quat="0.5 0.5 -0.5 0.5" mesh="feetech_pt_screw_2x6__configuration_default" material="feetech_pt_screw_2x6__configuration_default_material"/>
                    <geom type="mesh" class="collision" pos="0.0177 -0.07175 0.0477356" quat="0.5 0.5 -0.5 0.5" mesh="feetech_pt_screw_2x6__configuration_default" material="feetech_pt_screw_2x6__configuration_default_material"/>
                    <!-- Part j8_b_2_step -->
                    <geom type="mesh" class="visual" pos="-9.99999e-07 -0.260999 -0.17305" quat="0.707107 -0.707107 0 -0" mesh="j8_b_2_step" material="j8_b_2_step_material"/>
                    <geom type="mesh" class="collision" pos="-9.99999e-07 -0.260999 -0.17305" quat="0.707107 -0.707107 0 -0" mesh="j8_b_2_step" material="j8_b_2_step_material"/>
                    <!-- Part std00333_plast_tcb_torx_2_5x8__configuration_copy_of_default_3 -->
                    <geom type="mesh" class="visual" pos="0.0830084 -0.0650719 -0.0130486" quat="0.40558 -0.579228 -0.40558 -0.579228" mesh="std00333_plast_tcb_torx_2_5x8__configuration_copy_of_default" material="std00333_plast_tcb_torx_2_5x8__configuration_copy_of_default_material"/>
                    <geom type="mesh" class="collision" pos="0.0830084 -0.0650719 -0.0130486" quat="0.40558 -0.579228 -0.40558 -0.579228" mesh="std00333_plast_tcb_torx_2_5x8__configuration_copy_of_default" material="std00333_plast_tcb_torx_2_5x8__configuration_copy_of_default_material"/>
                    <!-- Part part_1__configuration_copy_of_2x8 -->
                    <geom type="mesh" class="visual" pos="0.03101 -0.0593 -0.04195" quat="0.707107 -0 -0.707107 -0" mesh="part_1__configuration_copy_of_2x8" material="part_1__configuration_copy_of_2x8_material"/>
                    <geom type="mesh" class="collision" pos="0.03101 -0.0593 -0.04195" quat="0.707107 -0 -0.707107 -0" mesh="part_1__configuration_copy_of_2x8" material="part_1__configuration_copy_of_2x8_material"/>
                    <!-- Part feetech_pt_screw_2x6__configuration_default_2 -->
                    <geom type="mesh" class="visual" pos="-0.0182 -0.0755 0.0477356" quat="0.5 -0.5 -0.5 -0.5" mesh="feetech_pt_screw_2x6__configuration_default" material="feetech_pt_screw_2x6__configuration_default_material"/>
                    <geom type="mesh" class="collision" pos="-0.0182 -0.0755 0.0477356" quat="0.5 -0.5 -0.5 -0.5" mesh="feetech_pt_screw_2x6__configuration_default" material="feetech_pt_screw_2x6__configuration_default_material"/>
                    <!-- Part std00333_plast_tcb_torx_2_5x8__configuration_copy_of_default_4 -->
                    <geom type="mesh" class="visual" pos="0.0830084 -0.0650719 -0.0420486" quat="0.40558 -0.579228 -0.40558 -0.579228" mesh="std00333_plast_tcb_torx_2_5x8__configuration_copy_of_default" material="std00333_plast_tcb_torx_2_5x8__configuration_copy_of_default_material"/>
                    <geom type="mesh" class="collision" pos="0.0830084 -0.0650719 -0.0420486" quat="0.40558 -0.579228 -0.40558 -0.579228" mesh="std00333_plast_tcb_torx_2_5x8__configuration_copy_of_default" material="std00333_plast_tcb_torx_2_5x8__configuration_copy_of_default_material"/>
                    <!-- Part cameras_holder_r -->
                    <geom type="mesh" class="visual" pos="0.0242 -0.120227 0.00285636" quat="0 -0.707107 0 -0.707107" mesh="cameras_holder_r" material="cameras_holder_r_material"/>
                    <geom type="mesh" class="collision" pos="0.0242 -0.120227 0.00285636" quat="0 -0.707107 0 -0.707107" mesh="cameras_holder_r" material="cameras_holder_r_material"/>
                    <!-- Part feetech_sts3215__configuration_default -->
                    <geom type="mesh" class="visual" pos="-0.0096 -0.079 0.0133" quat="0.707107 0 -0 0.707107" mesh="feetech_sts3215__configuration_default" material="feetech_sts3215__configuration_default_material"/>
                    <geom type="mesh" class="collision" pos="-0.0096 -0.079 0.0133" quat="0.707107 0 -0 0.707107" mesh="feetech_sts3215__configuration_default" material="feetech_sts3215__configuration_default_material"/>
                    <!-- Part feetech_pt_screw_2x6__configuration_default_3 -->
                    <geom type="mesh" class="visual" pos="0.0177 -0.07175 0.0682356" quat="0.5 0.5 -0.5 0.5" mesh="feetech_pt_screw_2x6__configuration_default" material="feetech_pt_screw_2x6__configuration_default_material"/>
                    <geom type="mesh" class="collision" pos="0.0177 -0.07175 0.0682356" quat="0.5 0.5 -0.5 0.5" mesh="feetech_pt_screw_2x6__configuration_default" material="feetech_pt_screw_2x6__configuration_default_material"/>
                    <!-- Part feetech_pt_screw_2x6__configuration_default_4 -->
                    <geom type="mesh" class="visual" pos="-0.0182 -0.0755 0.0682356" quat="0.5 -0.5 -0.5 -0.5" mesh="feetech_pt_screw_2x6__configuration_default" material="feetech_pt_screw_2x6__configuration_default_material"/>
                    <geom type="mesh" class="collision" pos="-0.0182 -0.0755 0.0682356" quat="0.5 -0.5 -0.5 -0.5" mesh="feetech_pt_screw_2x6__configuration_default" material="feetech_pt_screw_2x6__configuration_default_material"/>
                    <!-- Part gripper_base_r -->
                    <geom type="mesh" class="visual" pos="0.0242 -0.120227 0.00285636" quat="0 -0.707107 0 -0.707107" mesh="gripper_base_r" material="gripper_base_r_material"/>
                    <geom type="mesh" class="collision" pos="0.0242 -0.120227 0.00285636" quat="0 -0.707107 0 -0.707107" mesh="gripper_base_r" material="gripper_base_r_material"/>
                    <!-- Part arducam_fisheye -->
                    <geom type="mesh" class="visual" pos="0.0977284 -0.0670242 -0.0275486" quat="0.579228 0.40558 -0.579228 0.40558" mesh="arducam_fisheye" material="arducam_fisheye_material"/>
                    <geom type="mesh" class="collision" pos="0.0977284 -0.0670242 -0.0275486" quat="0.579228 0.40558 -0.579228 0.40558" mesh="arducam_fisheye" material="arducam_fisheye_material"/>
                    <!-- Part 602_00009_phillips_flat_head__m2_x_0_40mm_thread__14mm_long_screw_92010a802 -->
                    <geom type="mesh" class="visual" pos="0.0400246 -0.072 0.00845136" quat="0.5 0.5 0.5 -0.5" mesh="602_00009_phillips_flat_head__m2_x_0_40mm_thread__14mm_long_screw_92010a802" material="602_00009_phillips_flat_head__m2_x_0_40mm_thread__14mm_long_screw_92010a802_material"/>
                    <geom type="mesh" class="collision" pos="0.0400246 -0.072 0.00845136" quat="0.5 0.5 0.5 -0.5" mesh="602_00009_phillips_flat_head__m2_x_0_40mm_thread__14mm_long_screw_92010a802" material="602_00009_phillips_flat_head__m2_x_0_40mm_thread__14mm_long_screw_92010a802_material"/>
                    <!-- Part std00333_plast_tcb_torx_2_5x8__configuration_copy_of_default_5 -->
                    <geom type="mesh" class="visual" pos="0.01535 -0.07946 -0.0489995" quat="0.5 0.5 -0.5 0.5" mesh="std00333_plast_tcb_torx_2_5x8__configuration_copy_of_default" material="std00333_plast_tcb_torx_2_5x8__configuration_copy_of_default_material"/>
                    <geom type="mesh" class="collision" pos="0.01535 -0.07946 -0.0489995" quat="0.5 0.5 -0.5 0.5" mesh="std00333_plast_tcb_torx_2_5x8__configuration_copy_of_default" material="std00333_plast_tcb_torx_2_5x8__configuration_copy_of_default_material"/>
                    <!-- Part bulkhead -->
                    <geom type="mesh" class="visual" pos="0.01845 -0.0825 -0.0634995" quat="0.5 -0.5 0.5 0.5" mesh="bulkhead" material="bulkhead_material"/>
                    <geom type="mesh" class="collision" pos="0.01845 -0.0825 -0.0634995" quat="0.5 -0.5 0.5 0.5" mesh="bulkhead" material="bulkhead_material"/>
                    <!-- Part std00333_plast_tcb_torx_2_5x8__configuration_copy_of_default_6 -->
                    <geom type="mesh" class="visual" pos="0.110259 -0.0749905 -0.0130486" quat="0.40558 -0.579228 -0.40558 -0.579228" mesh="std00333_plast_tcb_torx_2_5x8__configuration_copy_of_default" material="std00333_plast_tcb_torx_2_5x8__configuration_copy_of_default_material"/>
                    <geom type="mesh" class="collision" pos="0.110259 -0.0749905 -0.0130486" quat="0.40558 -0.579228 -0.40558 -0.579228" mesh="std00333_plast_tcb_torx_2_5x8__configuration_copy_of_default" material="std00333_plast_tcb_torx_2_5x8__configuration_copy_of_default_material"/>
                    <!-- Part hex_socket_head_cap_screw_m4x0_70_x_8__a416dc2a8d778a4ef6150c0739aa89d1_2 -->
                    <geom type="mesh" class="visual" pos="0.0554246 -0.0485 -0.0365486" quat="0.5 -0.5 -0.5 -0.5" mesh="hex_socket_head_cap_screw_m4x0_70_x_8__a416dc2a8d778a4ef6150c0739aa89d1" material="hex_socket_head_cap_screw_m4x0_70_x_8__a416dc2a8d778a4ef6150c0739aa89d1_material"/>
                    <geom type="mesh" class="collision" pos="0.0554246 -0.0485 -0.0365486" quat="0.5 -0.5 -0.5 -0.5" mesh="hex_socket_head_cap_screw_m4x0_70_x_8__a416dc2a8d778a4ef6150c0739aa89d1" material="hex_socket_head_cap_screw_m4x0_70_x_8__a416dc2a8d778a4ef6150c0739aa89d1_material"/>
                    <!-- Part 602_00009_phillips_flat_head__m2_x_0_40mm_thread__14mm_long_screw_92010a802_2 -->
                    <geom type="mesh" class="visual" pos="0.0400246 -0.072 0.00845136" quat="0.5 0.5 0.5 -0.5" mesh="602_00009_phillips_flat_head__m2_x_0_40mm_thread__14mm_long_screw_92010a802_2" material="602_00009_phillips_flat_head__m2_x_0_40mm_thread__14mm_long_screw_92010a802_2_material"/>
                    <geom type="mesh" class="collision" pos="0.0400246 -0.072 0.00845136" quat="0.5 0.5 0.5 -0.5" mesh="602_00009_phillips_flat_head__m2_x_0_40mm_thread__14mm_long_screw_92010a802_2" material="602_00009_phillips_flat_head__m2_x_0_40mm_thread__14mm_long_screw_92010a802_2_material"/>
                    <!-- Part 606_00020_sr_front_cover -->
                    <geom type="mesh" class="visual" pos="0.0400246 -0.072 0.00845136" quat="0.5 0.5 0.5 -0.5" mesh="606_00020_sr_front_cover" material="606_00020_sr_front_cover_material"/>
                    <geom type="mesh" class="collision" pos="0.0400246 -0.072 0.00845136" quat="0.5 0.5 0.5 -0.5" mesh="606_00020_sr_front_cover" material="606_00020_sr_front_cover_material"/>
                    <!-- Part part_1__configuration_copy_of_2x8_2 -->
                    <geom type="mesh" class="visual" pos="0.03101 -0.0823 0.01605" quat="0.707107 0 -0.707107 -0" mesh="part_1__configuration_copy_of_2x8" material="part_1__configuration_copy_of_2x8_material"/>
                    <geom type="mesh" class="collision" pos="0.03101 -0.0823 0.01605" quat="0.707107 0 -0.707107 -0" mesh="part_1__configuration_copy_of_2x8" material="part_1__configuration_copy_of_2x8_material"/>
                    <!-- Part j8_a_2_step -->
                    <geom type="mesh" class="visual" pos="1e-12 -0.261 -0.17305" quat="0.707107 -0.707107 -0 -0" mesh="j8_a_2_step" material="j8_a_2_step_material"/>
                    <geom type="mesh" class="collision" pos="1e-12 -0.261 -0.17305" quat="0.707107 -0.707107 -0 -0" mesh="j8_a_2_step" material="j8_a_2_step_material"/>
                    <!-- Part 602_00009_phillips_flat_head__m2_x_0_40mm_thread__14mm_long_screw_92010a802_3 -->
                    <geom type="mesh" class="visual" pos="0.0400246 -0.072 0.00845136" quat="0.5 0.5 0.5 -0.5" mesh="602_00009_phillips_flat_head__m2_x_0_40mm_thread__14mm_long_screw_92010a802_3" material="602_00009_phillips_flat_head__m2_x_0_40mm_thread__14mm_long_screw_92010a802_3_material"/>
                    <geom type="mesh" class="collision" pos="0.0400246 -0.072 0.00845136" quat="0.5 0.5 0.5 -0.5" mesh="602_00009_phillips_flat_head__m2_x_0_40mm_thread__14mm_long_screw_92010a802_3" material="602_00009_phillips_flat_head__m2_x_0_40mm_thread__14mm_long_screw_92010a802_3_material"/>
                    <!-- Part grip_soft_tip_r -->
                    <geom type="mesh" class="visual" pos="0.0242 -0.120227 0.00285636" quat="0 -0.707107 -0 -0.707107" mesh="grip_soft_tip_r" material="grip_soft_tip_r_material"/>
                    <geom type="mesh" class="collision" pos="0.0242 -0.120227 0.00285636" quat="0 -0.707107 -0 -0.707107" mesh="grip_soft_tip_r" material="grip_soft_tip_r_material"/>
                    <!-- Part feetech_pt_screw_2x6__configuration_default_5 -->
                    <geom type="mesh" class="visual" pos="-0.0182 -0.0962 0.0682356" quat="0.5 -0.5 -0.5 -0.5" mesh="feetech_pt_screw_2x6__configuration_default" material="feetech_pt_screw_2x6__configuration_default_material"/>
                    <geom type="mesh" class="collision" pos="-0.0182 -0.0962 0.0682356" quat="0.5 -0.5 -0.5 -0.5" mesh="feetech_pt_screw_2x6__configuration_default" material="feetech_pt_screw_2x6__configuration_default_material"/>
                    <!-- Part hexalobular_socket_pan_head_screw_m2_5x0_45_x_6__a0337967dd2415a96d32f4de9af75974 -->
                    <geom type="mesh" class="visual" pos="0.03161 -0.0593 0.01605" quat="0 -0.707107 0 -0.707107" mesh="hexalobular_socket_pan_head_screw_m2_5x0_45_x_6__a0337967dd2415a96d32f4de9af75974" material="hexalobular_socket_pan_head_screw_m2_5x0_45_x_6__a0337967dd2415a96d32f4de9af75974_material"/>
                    <geom type="mesh" class="collision" pos="0.03161 -0.0593 0.01605" quat="0 -0.707107 0 -0.707107" mesh="hexalobular_socket_pan_head_screw_m2_5x0_45_x_6__a0337967dd2415a96d32f4de9af75974" material="hexalobular_socket_pan_head_screw_m2_5x0_45_x_6__a0337967dd2415a96d32f4de9af75974_material"/>
                    <!-- Part std00333_plast_tcb_torx_2_5x8__configuration_copy_of_default_7 -->
                    <geom type="mesh" class="visual" pos="0.0404 -0.0449 -0.0426436" quat="0.5 0.5 -0.5 0.5" mesh="std00333_plast_tcb_torx_2_5x8__configuration_copy_of_default" material="std00333_plast_tcb_torx_2_5x8__configuration_copy_of_default_material"/>
                    <geom type="mesh" class="collision" pos="0.0404 -0.0449 -0.0426436" quat="0.5 0.5 -0.5 0.5" mesh="std00333_plast_tcb_torx_2_5x8__configuration_copy_of_default" material="std00333_plast_tcb_torx_2_5x8__configuration_copy_of_default_material"/>
                    <!-- Part 602_00009_phillips_flat_head__m2_x_0_40mm_thread__14mm_long_screw_92010a802_1 -->
                    <geom type="mesh" class="visual" pos="0.0400246 -0.072 0.00845136" quat="0.5 0.5 0.5 -0.5" mesh="602_00009_phillips_flat_head__m2_x_0_40mm_thread__14mm_long_screw_92010a802_1" material="602_00009_phillips_flat_head__m2_x_0_40mm_thread__14mm_long_screw_92010a802_1_material"/>
                    <geom type="mesh" class="collision" pos="0.0400246 -0.072 0.00845136" quat="0.5 0.5 0.5 -0.5" mesh="602_00009_phillips_flat_head__m2_x_0_40mm_thread__14mm_long_screw_92010a802_1" material="602_00009_phillips_flat_head__m2_x_0_40mm_thread__14mm_long_screw_92010a802_1_material"/>
                    <!-- Part feetech_pt_screw_2x6__configuration_default_6 -->
                    <geom type="mesh" class="visual" pos="-0.0182 -0.0962 0.0477356" quat="0.5 -0.5 -0.5 -0.5" mesh="feetech_pt_screw_2x6__configuration_default" material="feetech_pt_screw_2x6__configuration_default_material"/>
                    <geom type="mesh" class="collision" pos="-0.0182 -0.0962 0.0477356" quat="0.5 -0.5 -0.5 -0.5" mesh="feetech_pt_screw_2x6__configuration_default" material="feetech_pt_screw_2x6__configuration_default_material"/>
                    <!-- Part std00333_plast_tcb_torx_2_5x8__configuration_copy_of_default_8 -->
                    <geom type="mesh" class="visual" pos="0.019 -0.13453 -0.0686628" quat="0.589226 -0.390912 -0.390912 -0.589226" mesh="std00333_plast_tcb_torx_2_5x8__configuration_copy_of_default" material="std00333_plast_tcb_torx_2_5x8__configuration_copy_of_default_material"/>
                    <geom type="mesh" class="collision" pos="0.019 -0.13453 -0.0686628" quat="0.589226 -0.390912 -0.390912 -0.589226" mesh="std00333_plast_tcb_torx_2_5x8__configuration_copy_of_default" material="std00333_plast_tcb_torx_2_5x8__configuration_copy_of_default_material"/>
                    <!-- Part 612_00001_tim_thermal_oak_d_poe -->
                    <geom type="mesh" class="visual" pos="0.0400246 -0.072 0.00845136" quat="0.5 0.5 0.5 -0.5" mesh="612_00001_tim_thermal_oak_d_poe" material="612_00001_tim_thermal_oak_d_poe_material"/>
                    <geom type="mesh" class="collision" pos="0.0400246 -0.072 0.00845136" quat="0.5 0.5 0.5 -0.5" mesh="612_00001_tim_thermal_oak_d_poe" material="612_00001_tim_thermal_oak_d_poe_material"/>
                    <!-- Part hub_dyn -->
                    <geom type="mesh" class="visual" pos="0.02381 -0.0858 -0.04545" quat="0.707107 0 -0.707107 -0" mesh="hub_dyn" material="hub_dyn_material"/>
                    <geom type="mesh" class="collision" pos="0.02381 -0.0858 -0.04545" quat="0.707107 0 -0.707107 -0" mesh="hub_dyn" material="hub_dyn_material"/>
                    <!-- Part grip_shell_r -->
                    <geom type="mesh" class="visual" pos="0.0242 -0.120227 0.00285636" quat="0 -0.707107 0 -0.707107" mesh="grip_shell_r" material="grip_shell_r_material"/>
                    <geom type="mesh" class="collision" pos="0.0242 -0.120227 0.00285636" quat="0 -0.707107 0 -0.707107" mesh="grip_shell_r" material="grip_shell_r_material"/>
                    <!-- Part std00333_plast_tcb_torx_2_5x8__configuration_copy_of_default_9 -->
                    <geom type="mesh" class="visual" pos="0.110259 -0.0749905 -0.0420486" quat="0.40558 -0.579228 -0.40558 -0.579228" mesh="std00333_plast_tcb_torx_2_5x8__configuration_copy_of_default" material="std00333_plast_tcb_torx_2_5x8__configuration_copy_of_default_material"/>
                    <geom type="mesh" class="collision" pos="0.110259 -0.0749905 -0.0420486" quat="0.40558 -0.579228 -0.40558 -0.579228" mesh="std00333_plast_tcb_torx_2_5x8__configuration_copy_of_default" material="std00333_plast_tcb_torx_2_5x8__configuration_copy_of_default_material"/>
                    <!-- Part hexalobular_socket_pan_head_screw_m2_5x0_45_x_6__a0337967dd2415a96d32f4de9af75974_2 -->
                    <geom type="mesh" class="visual" pos="0.03161 -0.0823 -0.04195" quat="0 -0.707107 0 -0.707107" mesh="hexalobular_socket_pan_head_screw_m2_5x0_45_x_6__a0337967dd2415a96d32f4de9af75974" material="hexalobular_socket_pan_head_screw_m2_5x0_45_x_6__a0337967dd2415a96d32f4de9af75974_material"/>
                    <geom type="mesh" class="collision" pos="0.03161 -0.0823 -0.04195" quat="0 -0.707107 0 -0.707107" mesh="hexalobular_socket_pan_head_screw_m2_5x0_45_x_6__a0337967dd2415a96d32f4de9af75974" material="hexalobular_socket_pan_head_screw_m2_5x0_45_x_6__a0337967dd2415a96d32f4de9af75974_material"/>
                    <!-- Part 606_00021_sr_back_cover_py074 -->
                    <geom type="mesh" class="visual" pos="0.0400246 -0.072 0.00845136" quat="0.5 0.5 0.5 -0.5" mesh="606_00021_sr_back_cover_py074" material="606_00021_sr_back_cover_py074_material"/>
                    <geom type="mesh" class="collision" pos="0.0400246 -0.072 0.00845136" quat="0.5 0.5 0.5 -0.5" mesh="606_00021_sr_back_cover_py074" material="606_00021_sr_back_cover_py074_material"/>
                    <!-- Part feetech_screw_m3x6__configuration_default -->
                    <geom type="mesh" class="visual" pos="-0.01905 -0.1045 0.0702128" quat="0.5 -0.5 -0.5 -0.5" mesh="feetech_screw_m3x6__configuration_default" material="feetech_screw_m3x6__configuration_default_material"/>
                    <geom type="mesh" class="collision" pos="-0.01905 -0.1045 0.0702128" quat="0.5 -0.5 -0.5 -0.5" mesh="feetech_screw_m3x6__configuration_default" material="feetech_screw_m3x6__configuration_default_material"/>
                    <!-- Part lens_adhesive -->
                    <geom type="mesh" class="visual" pos="0.0400246 -0.072 0.00845136" quat="0.5 0.5 0.5 -0.5" mesh="lens_adhesive" material="lens_adhesive_material"/>
                    <geom type="mesh" class="collision" pos="0.0400246 -0.072 0.00845136" quat="0.5 0.5 0.5 -0.5" mesh="lens_adhesive" material="lens_adhesive_material"/>
                    <!-- Part 611_00020 -->
                    <geom type="mesh" class="visual" pos="0.0400246 -0.072 0.00845136" quat="0.5 0.5 0.5 -0.5" mesh="611_00020" material="611_00020_material"/>
                    <geom type="mesh" class="collision" pos="0.0400246 -0.072 0.00845136" quat="0.5 0.5 0.5 -0.5" mesh="611_00020" material="611_00020_material"/>
                    <!-- Part std00333_plast_tcb_torx_2_5x8__configuration_copy_of_default_10 -->
                    <geom type="mesh" class="visual" pos="0.0404 -0.0449 -0.0126436" quat="0.5 0.5 -0.5 0.5" mesh="std00333_plast_tcb_torx_2_5x8__configuration_copy_of_default" material="std00333_plast_tcb_torx_2_5x8__configuration_copy_of_default_material"/>
                    <geom type="mesh" class="collision" pos="0.0404 -0.0449 -0.0126436" quat="0.5 0.5 -0.5 0.5" mesh="std00333_plast_tcb_torx_2_5x8__configuration_copy_of_default" material="std00333_plast_tcb_torx_2_5x8__configuration_copy_of_default_material"/>
                    <!-- Part rasp_pi_0_2w__configuration_default -->
                    <geom type="mesh" class="visual" pos="0.02872 -0.0708 -0.01295" quat="0.5 0.5 0.5 -0.5" mesh="rasp_pi_0_2w__configuration_default" material="rasp_pi_0_2w__configuration_default_material"/>
                    <geom type="mesh" class="collision" pos="0.02872 -0.0708 -0.01295" quat="0.5 0.5 0.5 -0.5" mesh="rasp_pi_0_2w__configuration_default" material="rasp_pi_0_2w__configuration_default_material"/>
                    <!-- Part std00333_plast_tcb_torx_2_5x8__configuration_copy_of_default_11 -->
                    <geom type="mesh" class="visual" pos="-0.01715 -0.07946 -0.0490995" quat="0.5 0.5 -0.5 0.5" mesh="std00333_plast_tcb_torx_2_5x8__configuration_copy_of_default" material="std00333_plast_tcb_torx_2_5x8__configuration_copy_of_default_material"/>
                    <geom type="mesh" class="collision" pos="-0.01715 -0.07946 -0.0490995" quat="0.5 0.5 -0.5 0.5" mesh="std00333_plast_tcb_torx_2_5x8__configuration_copy_of_default" material="std00333_plast_tcb_torx_2_5x8__configuration_copy_of_default_material"/>
                    <!-- Frame camera -->
                    <site group="3" name="camera" pos="0.0933847 -0.0789583 -0.0275486" quat="0.579228 0.40558 -0.579228 0.40558"/>
                    <!-- Frame gripper_base -->
                    <site group="3" name="gripper_base" pos="-0 -0.0495 -0.0205" quat="0.5 -0.5 -0.5 -0.5"/>
                    <!-- Frame oak_l -->
                    <site group="3" name="oak_l" pos="0.0530246 -0.078833 -0.0240486" quat="0.5 0.5 -0.5 0.5"/>
                    <!-- Frame oak_r -->
                    <site group="3" name="oak_r" pos="0.0530246 -0.078833 -0.00404864" quat="0.5 0.5 -0.5 0.5"/>
                    <!-- Frame gripper_center -->
                    <site group="3" name="gripper_center" pos="-0 -0.138087 -0.0240485" quat="0.5 -0.5 0.5 -0.5"/>
                    <!-- Frame thumb_tip -->
                    <site group="3" name="thumb_tip" pos="-0 -0.159661 -0.0777992" quat="0.655166 0.266002 -0.266002 0.655166"/>
                    <!-- Link feetech_sts3215__configuration_default -->
                    <body name="feetech_sts3215__configuration_default" pos="-0.01905 -0.1045 0.0133" quat="0.5 0.5 0.5 0.5">
                      <!-- Joint from j8_a_2_step to feetech_sts3215__configuration_default -->
                      <joint axis="0 0 1" name="proximal" type="hinge" range="0.0 1.5707963267948966"/>
                      <inertial pos="-0.0253697 0.0243883 0.0242046" mass="0.0769363" fullinertia="3.19064e-05 3.84967e-05 2.83826e-05 7.34138e-06 -4.06564e-06 3.31711e-06"/>
                      <!-- Part proximal_top_r -->
                      <geom type="mesh" class="visual" pos="-0.0157273 -0.0104436 0.04325" quat="0.707107 0 -0 0.707107" mesh="proximal_top_r" material="proximal_top_r_material"/>
                      <geom type="mesh" class="collision" pos="-0.0157273 -0.0104436 0.04325" quat="0.707107 0 -0 0.707107" mesh="proximal_top_r" material="proximal_top_r_material"/>
                      <!-- Part proximal_bot_r -->
                      <geom type="mesh" class="visual" pos="-0.0157273 -0.0104436 0.04325" quat="0.707107 0 0 0.707107" mesh="proximal_bot_r" material="proximal_bot_r_material"/>
                      <geom type="mesh" class="collision" pos="-0.0157273 -0.0104436 0.04325" quat="0.707107 0 0 0.707107" mesh="proximal_bot_r" material="proximal_bot_r_material"/>
                      <!-- Part feetech_screw_m3x6__configuration_default_2 -->
                      <geom type="mesh" class="visual" pos="0.007 0.0569128 -0.00245" quat="0.5 0.5 0.5 0.5" mesh="feetech_screw_m3x6__configuration_default" material="feetech_screw_m3x6__configuration_default_material"/>
                      <geom type="mesh" class="collision" pos="0.007 0.0569128 -0.00245" quat="0.5 0.5 0.5 0.5" mesh="feetech_screw_m3x6__configuration_default" material="feetech_screw_m3x6__configuration_default_material"/>
                      <!-- Part feetech_pt_screw_2x6__configuration_default_7 -->
                      <geom type="mesh" class="visual" pos="-0.0261619 0.0819783 0.03705" quat="0.5 -0.5 -0.5 0.5" mesh="feetech_pt_screw_2x6__configuration_default" material="feetech_pt_screw_2x6__configuration_default_material"/>
                      <geom type="mesh" class="collision" pos="-0.0261619 0.0819783 0.03705" quat="0.5 -0.5 -0.5 0.5" mesh="feetech_pt_screw_2x6__configuration_default" material="feetech_pt_screw_2x6__configuration_default_material"/>
                      <!-- Part feetech_screw_m3x6__configuration_default_3 -->
                      <geom type="mesh" class="visual" pos="-0.0115835 0.0823901 -0.0001" quat="0.606109 0.606109 0.364187 0.364187" mesh="feetech_screw_m3x6__configuration_default" material="feetech_screw_m3x6__configuration_default_material"/>
                      <geom type="mesh" class="collision" pos="-0.0115835 0.0823901 -0.0001" quat="0.606109 0.606109 0.364187 0.364187" mesh="feetech_screw_m3x6__configuration_default" material="feetech_screw_m3x6__configuration_default_material"/>
                      <!-- Part feetech_screw_m3x6__configuration_default_4 -->
                      <geom type="mesh" class="visual" pos="0 0.0639128 -0.00245" quat="0.5 0.5 0.5 0.5" mesh="feetech_screw_m3x6__configuration_default" material="feetech_screw_m3x6__configuration_default_material"/>
                      <geom type="mesh" class="collision" pos="0 0.0639128 -0.00245" quat="0.5 0.5 0.5 0.5" mesh="feetech_screw_m3x6__configuration_default" material="feetech_screw_m3x6__configuration_default_material"/>
                      <!-- Part feetech_pt_screw_2x6__configuration_default_8 -->
                      <geom type="mesh" class="visual" pos="-0.0078849 0.0722603 0.00055" quat="0.5 0.5 0.5 0.5" mesh="feetech_pt_screw_2x6__configuration_default" material="feetech_pt_screw_2x6__configuration_default_material"/>
                      <geom type="mesh" class="collision" pos="-0.0078849 0.0722603 0.00055" quat="0.5 0.5 0.5 0.5" mesh="feetech_pt_screw_2x6__configuration_default" material="feetech_pt_screw_2x6__configuration_default_material"/>
                      <!-- Part feetech_screw_m3x6__configuration_default_5 -->
                      <geom type="mesh" class="visual" pos="-0.007 0.0569128 0.04055" quat="0.5 -0.5 -0.5 0.5" mesh="feetech_screw_m3x6__configuration_default" material="feetech_screw_m3x6__configuration_default_material"/>
                      <geom type="mesh" class="collision" pos="-0.007 0.0569128 0.04055" quat="0.5 -0.5 -0.5 0.5" mesh="feetech_screw_m3x6__configuration_default" material="feetech_screw_m3x6__configuration_default_material"/>
                      <!-- Part proximal_shell_r -->
                      <geom type="mesh" class="visual" pos="-0.0157273 -0.0104436 0.04325" quat="0.707107 0 -0 0.707107" mesh="proximal_shell_r" material="proximal_shell_r_material"/>
                      <geom type="mesh" class="collision" pos="-0.0157273 -0.0104436 0.04325" quat="0.707107 0 -0 0.707107" mesh="proximal_shell_r" material="proximal_shell_r_material"/>
                      <!-- Part feetech_pt_screw_2x6__configuration_default_9 -->
                      <geom type="mesh" class="visual" pos="-0.014198 0.0523993 0.03705" quat="0.5 -0.5 -0.5 0.5" mesh="feetech_pt_screw_2x6__configuration_default" material="feetech_pt_screw_2x6__configuration_default_material"/>
                      <geom type="mesh" class="collision" pos="-0.014198 0.0523993 0.03705" quat="0.5 -0.5 -0.5 0.5" mesh="feetech_pt_screw_2x6__configuration_default" material="feetech_pt_screw_2x6__configuration_default_material"/>
                      <!-- Part feetech_screw_m3x6__configuration_default_6 -->
                      <geom type="mesh" class="visual" pos="-0.007 0.0569128 -0.00245" quat="0.5 0.5 0.5 0.5" mesh="feetech_screw_m3x6__configuration_default" material="feetech_screw_m3x6__configuration_default_material"/>
                      <geom type="mesh" class="collision" pos="-0.007 0.0569128 -0.00245" quat="0.5 0.5 0.5 0.5" mesh="feetech_screw_m3x6__configuration_default" material="feetech_screw_m3x6__configuration_default_material"/>
                      <!-- Part feetech_screw_m3x6__configuration_default_7 -->
                      <geom type="mesh" class="visual" pos="-0 0.0639128 0.04055" quat="0.5 -0.5 -0.5 0.5" mesh="feetech_screw_m3x6__configuration_default" material="feetech_screw_m3x6__configuration_default_material"/>
                      <geom type="mesh" class="collision" pos="-0 0.0639128 0.04055" quat="0.5 -0.5 -0.5 0.5" mesh="feetech_screw_m3x6__configuration_default" material="feetech_screw_m3x6__configuration_default_material"/>
                      <!-- Part feetech_screw_m3x6__configuration_default_8 -->
                      <geom type="mesh" class="visual" pos="0 0.0499128 -0.00245" quat="0.5 0.5 0.5 0.5" mesh="feetech_screw_m3x6__configuration_default" material="feetech_screw_m3x6__configuration_default_material"/>
                      <geom type="mesh" class="collision" pos="0 0.0499128 -0.00245" quat="0.5 0.5 0.5 0.5" mesh="feetech_screw_m3x6__configuration_default" material="feetech_screw_m3x6__configuration_default_material"/>
                      <!-- Part feetech_screw_m3x6__configuration_default_9 -->
                      <geom type="mesh" class="visual" pos="-0 0.0499128 0.04055" quat="0.5 -0.5 -0.5 0.5" mesh="feetech_screw_m3x6__configuration_default" material="feetech_screw_m3x6__configuration_default_material"/>
                      <geom type="mesh" class="collision" pos="-0 0.0499128 0.04055" quat="0.5 -0.5 -0.5 0.5" mesh="feetech_screw_m3x6__configuration_default" material="feetech_screw_m3x6__configuration_default_material"/>
                      <!-- Part feetech_pt_screw_2x6__configuration_default_10 -->
                      <geom type="mesh" class="visual" pos="-0.0175091 0.0541598 0.00055" quat="0.5 0.5 0.5 0.5" mesh="feetech_pt_screw_2x6__configuration_default" material="feetech_pt_screw_2x6__configuration_default_material"/>
                      <geom type="mesh" class="collision" pos="-0.0175091 0.0541598 0.00055" quat="0.5 0.5 0.5 0.5" mesh="feetech_pt_screw_2x6__configuration_default" material="feetech_pt_screw_2x6__configuration_default_material"/>
                      <!-- Part cross_bar -->
                      <geom type="mesh" class="visual" pos="-0.0157273 -0.0104436 0.04325" quat="0.707107 -0 -0 0.707107" mesh="cross_bar" material="cross_bar_material"/>
                      <geom type="mesh" class="collision" pos="-0.0157273 -0.0104436 0.04325" quat="0.707107 -0 -0 0.707107" mesh="cross_bar" material="cross_bar_material"/>
                      <!-- Part feetech_pt_screw_2x6__configuration_default_11 -->
                      <geom type="mesh" class="visual" pos="-0.00457385 0.0704997 0.03705" quat="0.5 -0.5 -0.5 0.5" mesh="feetech_pt_screw_2x6__configuration_default" material="feetech_pt_screw_2x6__configuration_default_material"/>
                      <geom type="mesh" class="collision" pos="-0.00457385 0.0704997 0.03705" quat="0.5 -0.5 -0.5 0.5" mesh="feetech_pt_screw_2x6__configuration_default" material="feetech_pt_screw_2x6__configuration_default_material"/>
                      <!-- Part feetech_screw_m3x6__configuration_default_10 -->
                      <geom type="mesh" class="visual" pos="0.007 0.0569128 0.04055" quat="0.5 -0.5 -0.5 0.5" mesh="feetech_screw_m3x6__configuration_default" material="feetech_screw_m3x6__configuration_default_material"/>
                      <geom type="mesh" class="collision" pos="0.007 0.0569128 0.04055" quat="0.5 -0.5 -0.5 0.5" mesh="feetech_screw_m3x6__configuration_default" material="feetech_screw_m3x6__configuration_default_material"/>
                      <!-- Part std00333_plast_tcb_torx_2_5x8__configuration_copy_of_default_12 -->
                      <geom type="mesh" class="visual" pos="-0.0298053 0.00790851 0.03925" quat="0.241842 0.241842 0.664464 0.664464" mesh="std00333_plast_tcb_torx_2_5x8__configuration_copy_of_default" material="std00333_plast_tcb_torx_2_5x8__configuration_copy_of_default_material"/>
                      <geom type="mesh" class="collision" pos="-0.0298053 0.00790851 0.03925" quat="0.241842 0.241842 0.664464 0.664464" mesh="std00333_plast_tcb_torx_2_5x8__configuration_copy_of_default" material="std00333_plast_tcb_torx_2_5x8__configuration_copy_of_default_material"/>
                      <!-- Part std00333_plast_tcb_torx_2_5x8__configuration_copy_of_default_13 -->
                      <geom type="mesh" class="visual" pos="-0.0298053 0.00790851 -0.00115" quat="0.241842 0.241842 0.664464 0.664464" mesh="std00333_plast_tcb_torx_2_5x8__configuration_copy_of_default" material="std00333_plast_tcb_torx_2_5x8__configuration_copy_of_default_material"/>
                      <geom type="mesh" class="collision" pos="-0.0298053 0.00790851 -0.00115" quat="0.241842 0.241842 0.664464 0.664464" mesh="std00333_plast_tcb_torx_2_5x8__configuration_copy_of_default" material="std00333_plast_tcb_torx_2_5x8__configuration_copy_of_default_material"/>
                      <!-- Part feetech_pt_screw_2x6__configuration_default_12 -->
                      <geom type="mesh" class="visual" pos="-0.0261619 0.0819783 0.00055" quat="0.5 0.5 0.5 0.5" mesh="feetech_pt_screw_2x6__configuration_default" material="feetech_pt_screw_2x6__configuration_default_material"/>
                      <geom type="mesh" class="collision" pos="-0.0261619 0.0819783 0.00055" quat="0.5 0.5 0.5 0.5" mesh="feetech_pt_screw_2x6__configuration_default" material="feetech_pt_screw_2x6__configuration_default_material"/>
                      <!-- Part feetech_sts3215__configuration_default_2 -->
                      <geom type="mesh" class="visual" pos="-0.0157873 0.0201676 0.00935" quat="0.686103 -0.686103 0.171065 -0.171065" mesh="feetech_sts3215__configuration_default" material="feetech_sts3215__configuration_default_material"/>
                      <geom type="mesh" class="collision" pos="-0.0157873 0.0201676 0.00935" quat="0.686103 -0.686103 0.171065 -0.171065" mesh="feetech_sts3215__configuration_default" material="feetech_sts3215__configuration_default_material"/>
                      <!-- Link distal_soft_tip -->
                      <body name="distal_soft_tip" pos="-0.0383025 0.0321391 -0.0001" quat="0.970296 0 0 -0.241922">
                        <!-- Joint from feetech_sts3215__configuration_default to distal_soft_tip -->
                        <joint axis="0 0 1" name="distal" type="hinge" range="0.0 1.5707963267948968"/>
                        <inertial pos="-0.0238598 -0.000329979 0.0190584" mass="0.0238623" fullinertia="7.50665e-06 1.03037e-05 6.05691e-06 -2.56698e-07 -2.063e-09 -3.57e-10"/>
                        <!-- Part feetech_screw_m3x6__configuration_default_11 -->
                        <geom type="mesh" class="visual" pos="-0.0197189 0.050251 -0.00215" quat="0.364187 0.364187 0.606109 0.606109" mesh="feetech_screw_m3x6__configuration_default" material="feetech_screw_m3x6__configuration_default_material"/>
                        <geom type="mesh" class="collision" pos="-0.0197189 0.050251 -0.00215" quat="0.364187 0.364187 0.606109 0.606109" mesh="feetech_screw_m3x6__configuration_default" material="feetech_screw_m3x6__configuration_default_material"/>
                        <!-- Part feetech_screw_m3x6__configuration_default_12 -->
                        <geom type="mesh" class="visual" pos="-0.0267189 0.043251 -0.00215" quat="0.364187 0.364187 0.606109 0.606109" mesh="feetech_screw_m3x6__configuration_default" material="feetech_screw_m3x6__configuration_default_material"/>
                        <geom type="mesh" class="collision" pos="-0.0267189 0.043251 -0.00215" quat="0.364187 0.364187 0.606109 0.606109" mesh="feetech_screw_m3x6__configuration_default" material="feetech_screw_m3x6__configuration_default_material"/>
                        <!-- Part feetech_screw_m3x6__configuration_default_13 -->
                        <geom type="mesh" class="visual" pos="-0.0337189 0.050251 0.04025" quat="0.364187 -0.364187 -0.606109 0.606109" mesh="feetech_screw_m3x6__configuration_default" material="feetech_screw_m3x6__configuration_default_material"/>
                        <geom type="mesh" class="collision" pos="-0.0337189 0.050251 0.04025" quat="0.364187 -0.364187 -0.606109 0.606109" mesh="feetech_screw_m3x6__configuration_default" material="feetech_screw_m3x6__configuration_default_material"/>
                        <!-- Part std00333_plast_tcb_torx_2_5x8__configuration_copy_of_default_14 -->
                        <geom type="mesh" class="visual" pos="-0.0345944 -0.00547559 0.03805" quat="0.516385 0.516385 0.483059 0.483059" mesh="std00333_plast_tcb_torx_2_5x8__configuration_copy_of_default" material="std00333_plast_tcb_torx_2_5x8__configuration_copy_of_default_material"/>
                        <geom type="mesh" class="collision" pos="-0.0345944 -0.00547559 0.03805" quat="0.516385 0.516385 0.483059 0.483059" mesh="std00333_plast_tcb_torx_2_5x8__configuration_copy_of_default" material="std00333_plast_tcb_torx_2_5x8__configuration_copy_of_default_material"/>
                        <!-- Part feetech_screw_m3x6__configuration_default_14 -->
                        <geom type="mesh" class="visual" pos="-0.0267189 0.043251 0.04025" quat="0.364187 -0.364187 -0.606109 0.606109" mesh="feetech_screw_m3x6__configuration_default" material="feetech_screw_m3x6__configuration_default_material"/>
                        <geom type="mesh" class="collision" pos="-0.0267189 0.043251 0.04025" quat="0.364187 -0.364187 -0.606109 0.606109" mesh="feetech_screw_m3x6__configuration_default" material="feetech_screw_m3x6__configuration_default_material"/>
                        <!-- Part feetech_screw_m3x6__configuration_default_15 -->
                        <geom type="mesh" class="visual" pos="-0.0197189 0.050251 0.04025" quat="0.364187 -0.364187 -0.606109 0.606109" mesh="feetech_screw_m3x6__configuration_default" material="feetech_screw_m3x6__configuration_default_material"/>
                        <geom type="mesh" class="collision" pos="-0.0197189 0.050251 0.04025" quat="0.364187 -0.364187 -0.606109 0.606109" mesh="feetech_screw_m3x6__configuration_default" material="feetech_screw_m3x6__configuration_default_material"/>
                        <!-- Part std00333_plast_tcb_torx_2_5x8__configuration_copy_of_default_15 -->
                        <geom type="mesh" class="visual" pos="-0.0345597 0.0100566 0.01905" quat="0.516385 0.516385 0.483059 0.483059" mesh="std00333_plast_tcb_torx_2_5x8__configuration_copy_of_default" material="std00333_plast_tcb_torx_2_5x8__configuration_copy_of_default_material"/>
                        <geom type="mesh" class="collision" pos="-0.0345597 0.0100566 0.01905" quat="0.516385 0.516385 0.483059 0.483059" mesh="std00333_plast_tcb_torx_2_5x8__configuration_copy_of_default" material="std00333_plast_tcb_torx_2_5x8__configuration_copy_of_default_material"/>
                        <!-- Part std00333_plast_tcb_torx_2_5x8__configuration_copy_of_default_16 -->
                        <geom type="mesh" class="visual" pos="-0.0345944 -0.00547559 5e-05" quat="0.516385 0.516385 0.483059 0.483059" mesh="std00333_plast_tcb_torx_2_5x8__configuration_copy_of_default" material="std00333_plast_tcb_torx_2_5x8__configuration_copy_of_default_material"/>
                        <geom type="mesh" class="collision" pos="-0.0345944 -0.00547559 5e-05" quat="0.516385 0.516385 0.483059 0.483059" mesh="std00333_plast_tcb_torx_2_5x8__configuration_copy_of_default" material="std00333_plast_tcb_torx_2_5x8__configuration_copy_of_default_material"/>
                        <!-- Part feetech_screw_m3x6__configuration_default_16 -->
                        <geom type="mesh" class="visual" pos="-0.0337189 0.050251 -0.00215" quat="0.364187 0.364187 0.606109 0.606109" mesh="feetech_screw_m3x6__configuration_default" material="feetech_screw_m3x6__configuration_default_material"/>
                        <geom type="mesh" class="collision" pos="-0.0337189 0.050251 -0.00215" quat="0.364187 0.364187 0.606109 0.606109" mesh="feetech_screw_m3x6__configuration_default" material="feetech_screw_m3x6__configuration_default_material"/>
                        <!-- Part distal_soft_tip -->
                        <geom type="mesh" class="visual" pos="0.039924 -0.0269999 0.04325" quat="0.515038 0 0 0.857167" mesh="distal_soft_tip" material="distal_soft_tip_material"/>
                        <geom type="mesh" class="collision" pos="0.039924 -0.0269999 0.04325" quat="0.515038 0 0 0.857167" mesh="distal_soft_tip" material="distal_soft_tip_material"/>
                        <!-- Part feetech_screw_m3x6__configuration_default_17 -->
                        <geom type="mesh" class="visual" pos="-0.0267189 0.057251 0.04025" quat="0.364187 -0.364187 -0.606109 0.606109" mesh="feetech_screw_m3x6__configuration_default" material="feetech_screw_m3x6__configuration_default_material"/>
                        <geom type="mesh" class="collision" pos="-0.0267189 0.057251 0.04025" quat="0.364187 -0.364187 -0.606109 0.606109" mesh="feetech_screw_m3x6__configuration_default" material="feetech_screw_m3x6__configuration_default_material"/>
                        <!-- Part feetech_screw_m3x6__configuration_default_18 -->
                        <geom type="mesh" class="visual" pos="-0.0267189 0.057251 -0.00215" quat="0.364187 0.364187 0.606109 0.606109" mesh="feetech_screw_m3x6__configuration_default" material="feetech_screw_m3x6__configuration_default_material"/>
                        <geom type="mesh" class="collision" pos="-0.0267189 0.057251 -0.00215" quat="0.364187 0.364187 0.606109 0.606109" mesh="feetech_screw_m3x6__configuration_default" material="feetech_screw_m3x6__configuration_default_material"/>
                        <!-- Part distal_r -->
                        <geom type="mesh" class="visual" pos="0.039924 -0.0269999 0.04325" quat="0.515038 0 0 0.857167" mesh="distal_r" material="distal_r_material"/>
                        <geom type="mesh" class="collision" pos="0.039924 -0.0269999 0.04325" quat="0.515038 0 0 0.857167" mesh="distal_r" material="distal_r_material"/>
                        <!-- Frame finger_tip -->
                        <site group="3" name="finger_tip" pos="-0.0613312 -0.00504543 0.01905" quat="0.153876 -0.153876 -0.690161 0.690161"/>
                      </body>
                    </body>
                  </body>
                </body>
              </body>
            </body>
          </body>
        </body>
      </body>
    </body>
  </worldbody>
  <asset>
    <mesh file="proximal_bot_r.stl"/>
    <mesh file="feetech_pt_screw_2x6__configuration_default.stl"/>
    <mesh file="grip_shell_r.stl"/>
    <mesh file="feetech_sts3215__configuration_default.stl"/>
    <mesh file="arducam_fisheye.stl"/>
    <mesh file="dm_j4310_1_2_step.stl"/>
    <mesh file="std00333_plast_tcb_torx_2_5x8__configuration_copy_of_default.stl"/>
    <mesh file="602_00009_phillips_flat_head__m2_x_0_40mm_thread__14mm_long_screw_92010a802.stl"/>
    <mesh file="distal_soft_tip.stl"/>
    <mesh file="j7_a_2_step.stl"/>
    <mesh file="j7_b_2_step_2.stl"/>
    <mesh file="j4_a_2_step.stl"/>
    <mesh file="cross_bar.stl"/>
    <mesh file="602_00009_phillips_flat_head__m2_x_0_40mm_thread__14mm_long_screw_92010a802_1.stl"/>
    <mesh file="612_00001_tim_thermal_oak_d_poe.stl"/>
    <mesh file="hub_dyn.stl"/>
    <mesh file="j4_d_2_step.stl"/>
    <mesh file="lens_adhesive.stl"/>
    <mesh file="611_00020_1.stl"/>
    <mesh file="j6_a_3_step.stl"/>
    <mesh file="j6_b_3_step.stl"/>
    <mesh file="bulkhead.stl"/>
    <mesh file="grip_soft_tip_r.stl"/>
    <mesh file="j4_c_2_step.stl"/>
    <mesh file="hex_socket_head_cap_screw_m4x0_70_x_8__a416dc2a8d778a4ef6150c0739aa89d1.stl"/>
    <mesh file="distal_r.stl"/>
    <mesh file="dm_j4310_1_2_step_1.stl"/>
    <mesh file="sr_lens_py058.stl"/>
    <mesh file="j2_b_2_step.stl"/>
    <mesh file="dm_j4310_1_2_step_2.stl"/>
    <mesh file="j2_c_2_step.stl"/>
    <mesh file="fl6700zz_2_step.stl"/>
    <mesh file="cameras_holder_r.stl"/>
    <mesh file="fl6803zz_2_step.stl"/>
    <mesh file="j1_d_1_step.stl"/>
    <mesh file="rasp_pi_0_2w__configuration_default.stl"/>
    <mesh file="dm_j4340p_2_step.stl"/>
    <mesh file="hexalobular_socket_pan_head_screw_m2_5x0_45_x_6__a0337967dd2415a96d32f4de9af75974.stl"/>
    <mesh file="proximal_shell_r.stl"/>
    <mesh file="606_00020_sr_front_cover.stl"/>
    <mesh file="j2_a_1_step.stl"/>
    <mesh file="j5_a_3_step.stl"/>
    <mesh file="j6_c_right_2_step.stl"/>
    <mesh file="602_00009_phillips_flat_head__m2_x_0_40mm_thread__14mm_long_screw_92010a802_3.stl"/>
    <mesh file="gripper_base_r.stl"/>
    <mesh file="feetech_screw_m3x6__configuration_default.stl"/>
    <mesh file="dm_j8009p_2_step.stl"/>
    <mesh file="j8_a_2_step.stl"/>
    <mesh file="j4_e_2_step.stl"/>
    <mesh file="proximal_top_r.stl"/>
    <mesh file="j1_a_1_step.stl"/>
    <mesh file="dm_j4340_2_step.stl"/>
    <mesh file="j1_e_1_step.stl"/>
    <mesh file="611_00020.stl"/>
    <mesh file="j8_b_2_step.stl"/>
    <mesh file="j4_b_2_step.stl"/>
    <mesh file="dm_j8009p_2_step_1.stl"/>
    <mesh file="j6_d_3_step.stl"/>
    <mesh file="j7_b_2_step.stl"/>
    <mesh file="j1_c_1_step.stl"/>
    <mesh file="j7_e_2_step.stl"/>
    <mesh file="j7_c_2_step.stl"/>
    <mesh file="fl6700zz_2_step_1.stl"/>
    <mesh file="j1_b_2_step.stl"/>
    <mesh file="602_00009_phillips_flat_head__m2_x_0_40mm_thread__14mm_long_screw_92010a802_2.stl"/>
    <mesh file="606_00021_sr_back_cover_py074.stl"/>
    <mesh file="part_1__configuration_copy_of_2x8.stl"/>
    <mesh file="hfsb6_6060_750_1_step.stl"/>
    <material name="j1_b_2_step_material" rgba="0.792157 0.819608 0.933333 1"/>
    <material name="hfsb6_6060_750_1_step_material" rgba="0.792157 0.819608 0.933333 1"/>
    <material name="dm_j8009p_2_step_material" rgba="0.792157 0.819608 0.933333 1"/>
    <material name="j1_a_1_step_material" rgba="0.792157 0.819608 0.933333 1"/>
    <material name="dm_j8009p_2_step_1_material" rgba="0.792157 0.819608 0.933333 1"/>
    <material name="j1_e_1_step_material" rgba="0.792157 0.819608 0.933333 1"/>
    <material name="j1_d_1_step_material" rgba="0.792157 0.819608 0.933333 1"/>
    <material name="j1_c_1_step_material" rgba="0.792157 0.819608 0.933333 1"/>
    <material name="j2_a_1_step_material" rgba="0.792157 0.819608 0.933333 1"/>
    <material name="j2_c_2_step_material" rgba="0.792157 0.819608 0.933333 1"/>
    <material name="j2_b_2_step_material" rgba="0.792157 0.819608 0.933333 1"/>
    <material name="dm_j4340p_2_step_material" rgba="0.792157 0.819608 0.933333 1"/>
    <material name="fl6803zz_2_step_material" rgba="0.792157 0.819608 0.933333 1"/>
    <material name="j4_a_2_step_material" rgba="0.792157 0.819608 0.933333 1"/>
    <material name="dm_j4340_2_step_material" rgba="0.792157 0.819608 0.933333 1"/>
    <material name="j4_b_2_step_material" rgba="0.792157 0.819608 0.933333 1"/>
    <material name="j4_d_2_step_material" rgba="0.792157 0.819608 0.933333 1"/>
    <material name="j4_c_2_step_material" rgba="0.792157 0.819608 0.933333 1"/>
    <material name="dm_j4310_1_2_step_material" rgba="0.792157 0.819608 0.933333 1"/>
    <material name="j4_e_2_step_material" rgba="0.792157 0.819608 0.933333 1"/>
    <material name="j6_d_3_step_material" rgba="0.792157 0.819608 0.933333 1"/>
    <material name="dm_j4310_1_2_step_1_material" rgba="0.792157 0.819608 0.933333 1"/>
    <material name="j6_b_3_step_material" rgba="0.792157 0.819608 0.933333 1"/>
    <material name="j5_a_3_step_material" rgba="0.792157 0.819608 0.933333 1"/>
    <material name="j6_a_3_step_material" rgba="0.792157 0.819608 0.933333 1"/>
    <material name="j6_c_right_2_step_material" rgba="0.792157 0.819608 0.933333 1"/>
    <material name="j7_e_2_step_material" rgba="0.792157 0.819608 0.933333 1"/>
    <material name="fl6700zz_2_step_material" rgba="0.792157 0.819608 0.933333 1"/>
    <material name="dm_j4310_1_2_step_2_material" rgba="0.792157 0.819608 0.933333 1"/>
    <material name="j7_b_2_step_material" rgba="0.792157 0.819608 0.933333 1"/>
    <material name="j7_a_2_step_material" rgba="0.792157 0.819608 0.933333 1"/>
    <material name="j7_c_2_step_material" rgba="0.792157 0.819608 0.933333 1"/>
    <material name="fl6700zz_2_step_1_material" rgba="0.792157 0.819608 0.933333 1"/>
    <material name="j7_b_2_step_2_material" rgba="0.792157 0.819608 0.933333 1"/>
    <material name="611_00020_1_material" rgba="0 0 0 1"/>
    <material name="sr_lens_py058_material" rgba="0.262745 0.282353 0.301961 0.376471"/>
    <material name="std00333_plast_tcb_torx_2_5x8__configuration_copy_of_default_material" rgba="0.901961 0.901961 0.901961 1"/>
    <material name="hex_socket_head_cap_screw_m4x0_70_x_8__a416dc2a8d778a4ef6150c0739aa89d1_material" rgba="0.603922 0.647059 0.686275 1"/>
    <material name="feetech_pt_screw_2x6__configuration_default_material" rgba="0.901961 0.901961 0.901961 1"/>
    <material name="j8_b_2_step_material" rgba="0.792157 0.819608 0.933333 1"/>
    <material name="part_1__configuration_copy_of_2x8_material" rgba="0.901961 0.901961 0.901961 1"/>
    <material name="cameras_holder_r_material" rgba="0.262745 0.282353 0.301961 1"/>
    <material name="feetech_sts3215__configuration_default_material" rgba="0.647059 0.647059 0.647059 1"/>
    <material name="gripper_base_r_material" rgba="1 1 1 1"/>
    <material name="arducam_fisheye_material" rgba="0.235294 0.235294 0.235294 1"/>
    <material name="602_00009_phillips_flat_head__m2_x_0_40mm_thread__14mm_long_screw_92010a802_material" rgba="0 0 0 1"/>
    <material name="bulkhead_material" rgba="0.980392 0.713725 0.00392157 1"/>
    <material name="602_00009_phillips_flat_head__m2_x_0_40mm_thread__14mm_long_screw_92010a802_2_material" rgba="0 0 0 1"/>
    <material name="606_00020_sr_front_cover_material" rgba="0.262745 0.282353 0.301961 1"/>
    <material name="j8_a_2_step_material" rgba="0.792157 0.819608 0.933333 1"/>
    <material name="602_00009_phillips_flat_head__m2_x_0_40mm_thread__14mm_long_screw_92010a802_3_material" rgba="0 0 0 1"/>
    <material name="grip_soft_tip_r_material" rgba="0.301961 0.301961 0.301961 1"/>
    <material name="hexalobular_socket_pan_head_screw_m2_5x0_45_x_6__a0337967dd2415a96d32f4de9af75974_material" rgba="0.603922 0.647059 0.686275 1"/>
    <material name="602_00009_phillips_flat_head__m2_x_0_40mm_thread__14mm_long_screw_92010a802_1_material" rgba="0 0 0 1"/>
    <material name="612_00001_tim_thermal_oak_d_poe_material" rgba="0.596078 0.666667 0.686275 1"/>
    <material name="hub_dyn_material" rgba="0.615686 0.811765 0.929412 1"/>
    <material name="grip_shell_r_material" rgba="1 1 1 1"/>
    <material name="606_00021_sr_back_cover_py074_material" rgba="0.262745 0.282353 0.301961 1"/>
    <material name="feetech_screw_m3x6__configuration_default_material" rgba="0.901961 0.901961 0.901961 1"/>
    <material name="lens_adhesive_material" rgba="0.262745 0.282353 0.301961 1"/>
    <material name="611_00020_material" rgba="0 0 0 1"/>
    <material name="rasp_pi_0_2w__configuration_default_material" rgba="0.972549 0.529412 0.00392157 1"/>
    <material name="proximal_top_r_material" rgba="1 1 1 1"/>
    <material name="proximal_bot_r_material" rgba="1 1 1 1"/>
    <material name="proximal_shell_r_material" rgba="1 1 1 1"/>
    <material name="cross_bar_material" rgba="0.917647 0.917647 0.917647 1"/>
    <material name="distal_soft_tip_material" rgba="0.301961 0.301961 0.301961 1"/>
    <material name="distal_r_material" rgba="1 1 1 1"/>
  </asset>
  <actuator>
    <position class="openarm_gripette_right" name="r_arm_pitch" joint="r_arm_pitch" inheritrange="1"/>
    <position class="openarm_gripette_right" name="r_arm_roll" joint="r_arm_roll" inheritrange="1"/>
    <position class="openarm_gripette_right" name="r_arm_yaw" joint="r_arm_yaw" inheritrange="1"/>
    <position class="openarm_gripette_right" name="r_elbow" joint="r_elbow" inheritrange="1"/>
    <position class="openarm_gripette_right" name="r_wrist_yaw" joint="r_wrist_yaw" inheritrange="1"/>
    <position class="openarm_gripette_right" name="r_wrist_roll" joint="r_wrist_roll" inheritrange="1"/>
    <position class="openarm_gripette_right" name="r_wrist_pitch" joint="r_wrist_pitch" inheritrange="1"/>
    <position class="openarm_gripette_right" name="proximal" joint="proximal" inheritrange="1" kp="120"/>
    <position class="openarm_gripette_right" name="distal" joint="distal" inheritrange="1" kp="120"/>
  </actuator>
  <equality>
    <joint joint1="r_wrist_roll_mimic" joint2="r_wrist_roll" polycoef="0 -1.0 0 0 0"/>
  </equality>
</mujoco>
